<?xml version="1.0" ?>
<robot name="ur20">

  <link name="base_link">
    <visual>
      <geometry>
        <mesh filename="../meshes/visual/base.dae"/>
      </geometry>
    </visual>
    <collision>
      <geometry>
        <mesh filename="../meshes/collision/base.stl"/>
      </geometry>
    </collision>
  </link>

  <joint name="shoulder_pan_joint" type="revolute">
    <parent link="base_link"/>
    <child link="shoulder_link"/>
    <origin rpy="0 0 0" xyz="0 0 0.2363"/>
    <axis xyz="0 0 1"/>
    <limit effort="500" lower="-6.28" upper="6.28" velocity="2"/>
  </joint>

  <link name="shoulder_link">
    <visual>
      <geometry>
        <mesh filename="../meshes/visual/shoulder.dae"/>
      </geometry>
    </visual>
    <collision>
      <geometry>
        <mesh filename="../meshes/collision/shoulder.stl"/>
      </geometry>
    </collision>
  </link>

  <joint name="shoulder_lift_joint" type="revolute">
    <parent link="shoulder_link"/>
    <child link="upper_arm_link"/>
    <origin rpy="0 1.570796 0" xyz="0 0 0"/>
    <axis xyz="0 1 0"/>
    <limit effort="500" lower="-6.28" upper="6.28" velocity="2"/>
  </joint>

  <link name="upper_arm_link">
    <visual>
      <geometry>
        <mesh filename="../meshes/visual/upperarm.dae"/>
      </geometry>
    </visual>
    <collision>
      <geometry>
        <mesh filename="../meshes/collision/upperarm.stl"/>
      </geometry>
    </collision>
  </link>

  <joint name="elbow_joint" type="revolute">
    <parent link="upper_arm_link"/>
    <child link="forearm_link"/>
    <origin rpy="0 0 0" xyz="0 -0.2001 0.862"/>
    <axis xyz="0 1 0"/>
    <limit effort="300" lower="-3.14" upper="3.14" velocity="2"/>
  </joint>

  <link name="forearm_link">
    <visual>
      <geometry>
        <mesh filename="../meshes/visual/forearm.dae"/>
      </geometry>
    </visual>
    <collision>
      <geometry>
        <mesh filename="../meshes/collision/forearm.stl"/>
      </geometry>
    </collision>
  </link>

  <joint name="wrist_1_joint" type="revolute">
    <parent link="forearm_link"/>
    <child link="wrist_1_link"/>
    <origin rpy="0 1.570796 0" xyz="0 0 0.820"/>
    <axis xyz="0 1 0"/>
    <limit effort="100" lower="-6.28" upper="6.28" velocity="2.1"/>
  </joint>

  <link name="wrist_1_link">
    <visual>
      <geometry>
        <mesh filename="../meshes/visual/wrist1.dae"/>
      </geometry>
    </visual>
    <collision>
      <geometry>
        <mesh filename="../meshes/collision/wrist1.stl"/>
      </geometry>
    </collision>
  </link>

  <joint name="wrist_2_joint" type="revolute">
    <parent link="wrist_1_link"/>
    <child link="wrist_2_link"/>
    <origin rpy="0 0 0" xyz="0 0.150 0"/>
    <axis xyz="0 0 1"/>
    <limit effort="100" lower="-6.28" upper="6.28" velocity="2.1"/>
  </joint>

  <link name="wrist_2_link">
    <visual>
      <geometry>
        <mesh filename="../meshes/visual/wrist2.dae"/>
      </geometry>
    </visual>
    <collision>
      <geometry>
        <mesh filename="../meshes/collision/wrist2.stl"/>
      </geometry>
    </collision>
  </link>

  <joint name="wrist_3_joint" type="revolute">
    <parent link="wrist_2_link"/>
    <child link="wrist_3_link"/>
    <origin rpy="0 0 0" xyz="0 0 0.133"/>
    <axis xyz="0 1 0"/>
    <limit effort="100" lower="-6.28" upper="6.28" velocity="2.1"/>
  </joint>

  <link name="wrist_3_link">
    <visual>
      <geometry>
        <mesh filename="../meshes/visual/wrist3.dae"/>
      </geometry>
    </visual>
    <collision>
      <geometry>
        <mesh filename="../meshes/collision/wrist3.stl"/>
      </geometry>
    </collision>
  </link>

</robot>